<?xml version="1.0"?>
<robot name="unicycle">

<!-- LINKS -->

  <link name="body_link">
    <inertial>
      <mass value="1.5"/>
      <origin rpy="0  0  0" xyz="0  0  0"/>
      <inertia ixx="0.00425" ixy="0" ixz="0" iyy="0.00425" iyz="0" izz="0.0036"/>                     
    </inertial>
    <visual>
      <origin rpy="0  0  0" xyz="0 0 0"/>
      <geometry>
        <box size="0.12 0.12 0.14"/> 
      </geometry>
    </visual>

    <visual>
      <origin rpy="0  0  0" xyz="0.015 0 0.12"/>
      <geometry>
        <box size="0.01 0.04 0.1"/> 
      </geometry>
    </visual>
    <visual>
      <origin rpy="0  0  0" xyz="-0.015 0 0.12"/>
      <geometry>
        <box size="0.01 0.04 0.1"/> 
      </geometry>
    </visual>
    <visual>
      <origin rpy="0  1.5708  0" xyz="0.015 0 0.17"/>
      <geometry>
        <cylinder length="0.012" radius="0.02"/> 
      </geometry>
    </visual>
    <visual>
      <origin rpy="0  1.5708  0" xyz="-0.015 0 0.17"/>
      <geometry>
        <cylinder length="0.012" radius="0.02"/> 
      </geometry>
    </visual>

    <visual>
      <origin rpy="0  0  0" xyz="0 0.015 -0.12"/>
      <geometry>
        <box size="0.04 0.01 0.1"/> 
      </geometry>
    </visual>
    <visual>
      <origin rpy="0  0  0" xyz="0 -0.015 -0.12"/>
      <geometry>
        <box size="0.04 0.01 0.1"/> 
      </geometry>
    </visual>
    <visual>
      <origin rpy="1.5708  0  0" xyz="0 0.015 -0.17"/>
      <geometry>
        <cylinder length="0.012" radius="0.02"/> 
      </geometry>
    </visual>
    <visual>
      <origin rpy="1.5708  0  0" xyz="0 -0.015 -0.17"/>
      <geometry>
        <cylinder length="0.012" radius="0.02"/> 
      </geometry>
    </visual>

    <visual>
      <origin rpy="0  1.5708  0" xyz="-0.05 0 0.17"/>
      <geometry>
        <cylinder length="0.06" radius="0.03"/> 
      </geometry>
    </visual>

    <collision>
      <origin rpy="0  0  0" xyz="0 0 0"/>
      <geometry>
        <box size="0.12 0.12 0.14"/> 
      </geometry>
    </collision>
  </link>

  <link name="imu_link">
    <inertial>
      <mass value="0"/>
      <origin rpy="0 0 0" xyz="0 0 0"/>
      <inertia ixx="0" ixy="0" ixz="0" iyy="0" iyz="0" izz="0"/>
    </inertial>
    <visual>
      <origin rpy="0 0 0" xyz="0 0 0"/>
      <geometry>
        <box size="0.01 0.01 0.01"/>
      </geometry>
    </visual>
  </link> 

  <link name="wheel_link">
    <inertial>
      <mass value="0.5"/>
      <origin rpy="0  0  0" xyz="0  0  0"/>
      <inertia ixx="0.000329166" ixy="0" ixz="0" iyy="0.000625" iyz="0" izz="0.000329166"/>                      
    </inertial>
    <visual>
      <origin rpy="1.5708  0  0" xyz="0 0 0"/>
      <geometry>
        <!--<cylinder length="0.02" radius="0.05"/>-->
        <mesh filename="package://unicycle/meshes/wheel.stl"/>
      </geometry>
    </visual>
    <collision>
      <origin rpy="1.5708  0  0" xyz="0 0 0"/>
      <geometry>
        <!--<cylinder length="0.02" radius="0.05"/>-->
        <mesh filename="package://unicycle/meshes/wheel_simple.stl"/>
      </geometry>
    </collision>
  </link>

  <link name="disc_link">
    <inertial>
      <mass value="0.85"/>
      <origin rpy="0  0  0" xyz="0  0  0"/>
      <inertia ixx="0.00272" ixy="0" ixz="0" iyy="0.001388333" iyz="0" izz="0.001388333"/>                      <!-- -->
    </inertial>
    <visual>
      <origin rpy="0  1.5708  0" xyz="-0.007 0 0"/>
      <geometry>
        <cylinder length="0.006" radius="0.08"/> 
        <!--<mesh filename="package://unicycle/meshes/disk.stl"/>-->
      </geometry>
    </visual>
    <visual>
      <origin rpy="0  1.5708  0" xyz="0 0 0"/>
      <geometry>
        <cylinder length="0.02" radius="0.03"/> 
      </geometry>
    </visual>
    <visual>
      <origin rpy="0  1.5708  0" xyz="0 0 0.07"/>
      <geometry>
        <cylinder length="0.02" radius="0.01"/> 
      </geometry>
    </visual>
    <visual>
      <origin rpy="0  1.5708  0" xyz="0 0 -0.07"/>
      <geometry>
        <cylinder length="0.02" radius="0.01"/> 
      </geometry>
    </visual>
    <visual>
      <origin rpy="0  1.5708  0" xyz="0 0.07 0"/>
      <geometry>
        <cylinder length="0.02" radius="0.01"/> 
      </geometry>
    </visual>
    <visual>
      <origin rpy="0  1.5708  0" xyz="0 -0.07 0"/>
      <geometry>
        <cylinder length="0.02" radius="0.01"/> 
      </geometry>
    </visual>
    <collision>
      <origin rpy="0  1.5708 0" xyz="0 0 0"/>
      <geometry>
        <cylinder length="0.02" radius="0.08"/>
      </geometry>
    </collision>
  </link>

  <gazebo reference="wheel_link">
    <kp>1000000.0</kp>
    <kd>1.0</kd>
    <mu1>0.9</mu1>
    <mu2>0.9</mu2>
    <dampingFactor>0</dampingFactor>
    <fdir1>0 0 0</fdir1>
    <maxVel>50</maxVel>
    <minDepth>0.001</minDepth>
    <maxContacts>5</maxContacts>
    <material>Gazebo/Grey</material> 
  </gazebo> 

  <gazebo reference="disc_link">
    <material>Gazebo/DarkYellow</material> 
  </gazebo> 

  <gazebo reference="body_link">
    <material>Gazebo/White</material> 
  </gazebo> 


<!-- JOINTS -->
  <joint name="wheel" type="revolute">
    <parent link="body_link"/>
    <child link="wheel_link"/>
    <origin rpy="0      0      0" xyz="0   0  -0.17"/>
    <axis xyz="0  1  0"/>
    <!--<dynamics friction = "0.001"/> -->
    <limit effort="10.0" lower="-1.79769e+308" upper="1.79769e+308" velocity="150.0"/>
  </joint>

  <joint name="disc" type="revolute">
    <parent link="body_link"/>
    <child link="disc_link"/>
    <origin rpy="0      0      0" xyz="0   0  0.17"/>
    <axis xyz="1  0  0"/>
    <!--<dynamics friction = "0.001"/> -->
    <limit effort="10.0" lower="-1.79769e+308" upper="1.79769e+308" velocity="150.0"/>
  </joint>

  <joint name="body_imu_joint" type="fixed">
    <parent link="body_link"/>
    <child link="imu_link"/>
    <origin rpy="0 0 0" xyz="0 0 0"/>
  </joint>


<!-- TRANSMISSIONS -->
  <transmission name="wheel_trans">
    <type>transmission_interface/SimpleTransmission</type>
    <actuator name="wheel_motor">
      <mechanicalReduction>1</mechanicalReduction>
    </actuator>
    <joint name="wheel">
      <hardwareInterface>hardware_interface/EffortJointInterface</hardwareInterface>
    </joint>
  </transmission>

  <transmission name="disc_trans">
    <type>transmission_interface/SimpleTransmission</type>
    <actuator name="disc_motor">
      <mechanicalReduction>1</mechanicalReduction>
    </actuator>
    <joint name="disc">
      <hardwareInterface>hardware_interface/EffortJointInterface</hardwareInterface>
    </joint>
  </transmission>

<!-- GAZEBO PLUGINS-->
  <gazebo>
    <plugin name="gazebo_ros_control" filename="libgazebo_ros_control.so">
      <robotNamespace>/unicycle</robotNamespace>
      <legacyModeNS>true</legacyModeNS>
      <!-- robotSimType>gazebo_ros_control/DefaultRobotHWSim</robotSimType -->
      <!-- robotParam>/balancer/robot_description</robotParam -->
    </plugin>
  </gazebo>

  <gazebo reference="imu_link">
    <gravity>true</gravity>
    <sensor name="imu_sensor" type="imu">
      <always_on>true</always_on>
      <update_rate>200</update_rate>
      <visualize>true</visualize>
      <topic>__default_topic__</topic>
      <plugin filename="libgazebo_ros_imu_sensor.so" name="imu_plugin">
        <topicName>unicycle/imu_data</topicName>
        <bodyName>imu_link</bodyName>
        <updateRateHZ>200.0</updateRateHZ>
        <gaussianNoise>0.0</gaussianNoise>
        <xyzOffset>0 0 0</xyzOffset>
        <rpyOffset>0 0 0</rpyOffset>
        <frameName>imu_link</frameName>
        <initialOrientationAsReference>false</initialOrientationAsReference>
      </plugin>
      <pose>0 0 0 0 0 0</pose>
    </sensor>
  </gazebo> 

  <!--<gazebo>
    <plugin name="imu_body" filename="libgazebo_ros_imu.so">
      <alwaysOn>true</alwaysOn>
      <robotNamespace>/unicycle</robotNamespace>
      <topicName>imu_data</topicName>
      <bodyName>body_link</bodyName>
      <serviceName>/imu_service</serviceName>
      <gaussianNoise>0.0</gaussianNoise>    
      <updateRate>200.0</updateRate>
    </plugin>
  </gazebo> -->

</robot>





